Workbook

Sheet BP
A1: FLUMINENSE FOOTBALL CLUB — Balanço Patrimonial
A2: Em milhares de Reais | Série principal: 2023 reap + 2024 + 2025 sob critério ITG 2003 (R2) | 2022 = contexto histórico (R1, não comparável diretamente)
B4: 2022 (R1) | C4: 2023 reap (R2) | D4: 2024 (R2) | E4: 2025 (R2) | F4: Notas
A5: ATIVO
A6: Ativo Circulante
A7: Caixa e equivalentes de caixa | B7: 51 | C7: 41727 | D7: 10423 | E7: 34526
A8: Contas a receber | B8: 8110 | C8: 118424 | D8: 95397 | E8: 49894 | F8: Em 2024 inclui R$ 91.306 da Liga Forte (LFU/LFF), zerado em 2025
A9: Contas a receber na transferência de jogadores | B9: 46288 | C9: 24569 | D9: 67919 | E9: 78109
A10: Adiantamentos a fornecedores | B10: 7341 | C10: 17829 | D10: 4644 | E10: 16227
A11: Outros ativos | B11: 2714 | C11: 1496 | D11: 169 | E11: 2330
A12: Total Ativo Circulante | B12: =SUM(B7:B11) -> 64504 | C12: =SUM(C7:C11) -> 204045 | D12: =SUM(D7:D11) -> 178552 | E12: =SUM(E7:E11) -> 181086 | F12: Soma das linhas acima
A14: Ativo Não Circulante
A15: Contas a receber na transferência de jogadores (NC) | B15: 34207 | C15: 17409 | D15: 52089 | E15: 35580
A16: Depósitos judiciais | B16: 17096 | C16: 4206 | D16: 2268 | E16: 1878
A17: Investimentos (Fla-Flu Serviços S.A. — 35%) | B17: 0 | C17: 0 | D17: 1646 | E17: 3793 | F17: Concessão Maracanã 20 anos a partir de 27/09/2024
A18: Intangível | B18: 78054 | C18: 79860 | D18: 65506 | E18: 306803 | F18: Em 2025 inclui R$ 110.427 de "Direito de uso de Marca" (recompra FFU) — ressalva do auditor
A19: Imobilizado | B19: 335516 | C19: 332259 | D19: 332020 | E19: 331731 | F19: Terreno Laranjeiras R$ 152.000 (deemed cost 2012)
A20: Total Ativo Não Circulante | B20: =SUM(B15:B19) -> 464873 | C20: =SUM(C15:C19) -> 433734 | D20: =SUM(D15:D19) -> 453529 | E20: =SUM(E15:E19) -> 679785 | F20: Soma das linhas acima
A22: TOTAL DO ATIVO | B22: =B12+B20 -> 529377 | C22: =C12+C20 -> 637779 | D22: =D12+D20 -> 632081 | E22: =E12+E20 -> 860871 | F22: Circulante + Não Circulante
A24: PASSIVO E PATRIMÔNIO LÍQUIDO
A25: Passivo Circulante
A26: Fornecedores e outras obrigações | B26: 10488 | C26: 12653 | D26: 6024 | E26: 30165
A27: Contas a pagar na transferência de jogadores | B27: 27675 | C27: 31369 | D27: 78869 | E27: 196295 | F27: Aumento de 149% em 2025 — reflete parcelamento das 11 contratações
A28: Empréstimos e financiamentos | B28: 33418 | C28: 38558 | D28: 1479 | E28: 17125
A29: Tributos parcelados | B29: 28298 | C29: 36475 | D29: 65055 | E29: 59840
A30: Obrigações trabalhistas | B30: 42002 | C30: 50849 | D30: 47485 | E30: 58059 | F30: Folha de dezembro/2025 contabilizada (regime competência); paga em janeiro/2026
A31: Direitos de imagem a pagar | B31: 8176 | C31: 16694 | D31: 10343 | E31: 14620
A32: Tributos a recolher | B32: 20025 | C32: 20917 | D32: 39526 | E32: 33382
A33: Encargos sociais | B33: 26145 | C33: 24139 | D33: 33200 | E33: 16541
A34: Contas a pagar oriundos de acordos judiciais | B34: 54567 | C34: 61437 | D34: 94298 | E34: 53191 | F34: Nota 14 do PDF 2025 mostra R$ 42.510 — divergência interna com BP; usar BP
A35: Adiantamentos recebidos | B35: 40228 | C35: 30028 | D35: 5088 | E35: 773
A36: Outros passivos | B36: 2127 | C36: 8273 | D36: 10120 | E36: 3822
A37: Total Passivo Circulante | B37: =SUM(B26:B36) -> 293149 | C37: =SUM(C26:C36) -> 331392 | D37: =SUM(D26:D36) -> 391487 | E37: =SUM(E26:E36) -> 483813 | F37: Soma das linhas acima
A39: Passivo Não Circulante
A40: Contas a pagar na transferência de jogadores (NC) | B40: 23826 | C40: 26954 | D40: 20744 | E40: 47897
A41: Empréstimos e financiamentos (NC) | B41: 25748 | C41: 10711 | D41: 30000 | E41: 20650
A42: Tributos parcelados (NC) | B42: 285826 | C42: 340135 | D42: 327234 | E42: 410140 | F42: Inclui nova transação PGFN nov/2025 (englobou RFB) com desconto R$ 89.766
A43: Contas a pagar oriundos de acordos judiciais (NC) | B43: 25558 | C43: 78982 | D43: 72855 | E43: 38199
A44: Provisão para contingências | B44: 129876 | C44: 34640 | D44: 23391 | E44: 42217 | F44: Auditor 2025 indica déficit de provisão de R$ 34.176 — ressalva
A45: Adiantamentos recebidos (NC) | B45: 9330 | C45: 178 | D45: 0 | E45: 0
...

Sheet DRE
A1: FLUMINENSE FOOTBALL CLUB — Demonstração do Resultado (DRE)
A2: Em milhares de Reais | Estrutura DRE conforme PDF 2025 | 2022 (R1) parcialmente comparável — antes ITG 2003 (R2)
B4: 2022 (R1) | C4: 2023 reap (R2) | D4: 2024 (R2) | E4: 2025 (R2) | F4: Notas
A5: Receita operacional líquida | B5: 327933 | C5: 458713 | D5: 399624 | E5: 758546 | F5: Bruta menos impostos e direito de arena
A7: CUSTOS E DESPESAS OPERACIONAIS
A8: Remunerações, salários, encargos e benefícios | B8: -209835 | C8: -257820 | D8: -371159 | E8: -521663 | F8: Salto de 41% em 2025 — prêmios FIFA e novas contratações
A9: Transporte e outros gastos com jogos e competições | B9: -45213 | C9: -56178 | D9: -71975 | E9: -88419
A10: Serviços de terceiros, incluindo comissões sobre vendas | B10: -28456 | C10: -36529 | D10: -44118 | E10: -88941 | F10: Comissões cessão de atletas mais que dobraram
A11: Reversão (constituição) de provisão para contingências | B11: -8127 | C11: 9520 | D11: -9569 | E11: -30861
A12: Amortizações e baixas dos direitos de jogadores | B12: -22308 | C12: -18540 | D12: -32632 | E12: -84353
A13: Depreciações/amortizações de imobilizado e outros intangíveis | B13: -3829 | C13: -4112 | D13: -4440 | E13: -6762
A14: Tributos incidentes sobre operações de câmbio | B14: 0 | C14: -2814 | D14: -5248 | E14: -17667 | F14: Reflete tributação sobre receita FIFA Mundial e cessões em moeda estrangeira
A15: Resultado de Equivalência Patrimonial | B15: 0 | C15: 0 | D15: -1865 | E15: 7505 | F15: Fla-Flu Serviços S.A. (35% — Maracanã) virou positiva em 2025
A16: Gastos gerais | B16: -36782 | C16: -42375 | D16: -52295 | E16: -54138
A17: Total dos custos e despesas operacionais | B17: =SUM(B8:B16) -> -354550 | C17: =SUM(C8:C16) -> -408848 | D17: =SUM(D8:D16) -> -593301 | E17: =SUM(E8:E16) -> -885299 | F17: Soma das linhas acima
A19: OUTRAS RECEITAS E DESPESAS OPERACIONAIS
A20: Cessão de direitos econômicos de atletas e mecanismo de solidariedade | B20: 93930 | C20: 16106 | D20: 268169 | E20: 233378 | F20: 2025: Kauã Elias R$ 78,7M + Jhon Arias R$ 60,5M + Isaque R$ 55,2M = 83% do total
A21: Custo com registro de cessão de atletas e baixa de intangível | B21: -3568 | C21: -2185 | D21: -5720 | E21: -6255
A22: Total outras receitas/despesas operacionais | B22: =SUM(B20:B21) -> 90362 | C22: =SUM(C20:C21) -> 13921 | D22: =SUM(D20:D21) -> 262449 | E22: =SUM(E20:E21) -> 227123
A24: SUPERÁVIT ANTES DOS RESULTADOS FINANCEIROS (EBIT) | B24: =B5+B17+B22 -> 63745 | C24: =C5+C17+C22 -> 63786 | D24: =D5+D17+D22 -> 68772 | E24: =E5+E17+E22 -> 100370 | F24: Receita líquida + Custos/Despesas + Outras
A26: RESULTADO FINANCEIRO
A27: Receitas financeiras | B27: 5638 | C27: 8275 | D27: 10232 | E27: 119244 | F27: 2025: descontos PGFN R$ 93,8M (vs R$ 3M em 2024) — efeito único
A28: Despesas financeiras | B28: -39423 | C28: -47935 | D28: -78890 | E28: -168029 | F28: 2025: juros parcelamento R$ 21,9M + juros financiamento R$ 105,6M
A29: Resultado financeiro líquido | B29: =B27+B28 -> -33785 | C29: =C27+C28 -> -39660 | D29: =D27+D28 -> -68658 | E29: =E27+E28 -> -48785
A31: SUPERÁVIT/(DÉFICIT) DO EXERCÍCIO | B31: =B24+B29 -> 29960 | C31: =C24+C29 -> 24126 | D31: =D24+D29 -> 114 | E31: =E24+E29 -> 51585 | F31: EBIT + Resultado financeiro líquido
A33: VALIDAÇÃO: Superávit DRE vs. BP | B33: =B31-BP!B54 -> 29960 | C33: =C31-BP!C54 -> 24126 | D33: =D31-BP!D54 -> 0 | E33: =E31-BP!E54 -> 0 | F33: Deve ser zero (ou próximo de zero por arredondamento)
A35: INDICADORES DA DRE
A36: EBITDA reportado | B36: =B24-B12-B13 -> 89882 | C36: =C24-C12-C13 -> 86438 | D36: =D24-D12-D13 -> 105844 | E36: =E24-E12-E13 -> 191485 | F36: EBIT + Depreciações + Amortizações jogadores + Amortizações intangíveis
A37: EBITDA reportado (do Relatório de Gestão) | B37: 64202 | C37: 146866 | D37: 105844 | E37: 191485 | F37: Conferir contra cálculo da linha acima
A38: Margem EBITDA (% sobre Receita Líquida) | B38: =IFERROR(B36/B5,0) -> 0.27408647 | C38: =IFERROR(C36/C5,0) -> 0.18843591 | D38: =IFERROR(D36/D5,0) -> 0.26485897 | E38: =IFERROR(E36/E5,0) -> 0.2524369
A39: Margem Operacional (% sobre Receita Líquida) | B39: =IFERROR(B24/B5,0) -> 0.19438422 | C39: =IFERROR(C24/C5,0) -> 0.13905427 | D39: =IFERROR(D24/D5,0) -> 0.17209177 | E39: =IFERROR(E24/E5,0) -> 0.13231894
A40: Margem Líquida (% sobre Receita Líquida) | B40: =IFERROR(B31/B5,0) -> 0.091360125 | C40: =IFERROR(C31/C5,0) -> 0.052594978 | D40: =IFERROR(D31/D5,0) -> 0.00028526815 | E40: =IFERROR(E31/E5,0) -> 0.068005105

Sheet Receita_Detalhada
A1: FLUMINENSE FOOTBALL CLUB — Receita Bruta Detalhada por Categoria
A2: Em milhares de Reais | Receita Total SEM DEDUÇÕES conforme relatório de gestão | Decomposição com foco em separar recorrente de extraordinário
A4: Categoria | B4: 2019 | C4: 2020 | D4: 2021 | E4: 2022 | F4: 2023 | G4: 2024 | H4: 2025 | I4: Notas
A5: RECEITAS POR CATEGORIA
A6: Cessão de Direitos Econômicos de Atletas + Mec. Solidariedade | B6: 105415 | C6: 50333 | D6: 109593 | E6: 93930 | F6: 16106 | G6: 268169 | H6: 233378 | I6: 2024 e 2025 muito altos — concentração em 2-3 atletas/ano gera risco
A7: Direitos de Transmissão | B7: 80167 | C7: 69446 | D7: 95723 | E7: 83132 | F7: 89122 | G7: 98285 | H7: 162375 | I7: 2025: +65% vs 2024 — novo regime de centralização (LFU/LFF) + premiação mata-mata reconhecida em transmissão
A8: Premiação por Performance | B8: 27933 | C8: 18287 | D8: 81079 | E8: 68290 | F8: 188111 | G8: 68411 | H8: 363905 | I8: 2025: R$ 331,12M brutos da FIFA Mundial — não recorrente | 2023 Libertadores R$ 188M
A9: Patrocínios e Licenciamento | B9: 9352 | C9: 9769 | D9: 20102 | E9: 32552 | F9: 49630 | G9: 78274 | H9: 132129 | I9: 2025: salto com contrato PUMA + Superbet + ampliação rede lojas (35 lojas)
A10: Sócio Futebol | B10: 5348 | C10: 10554 | D10: 8762 | E10: 22273 | F10: 56781 | G10: 69864 | H10: 59684 | I10: 2025: ligeira queda mesmo com 8 mil sócios — possível churn pós-pandemia/queda em campo
A11: Bilheteria e Outras Receitas em Jogos | B11: 16384 | C11: 3205 | D11: 2555 | E11: 24372 | F11: 39263 | G11: 29192 | H11: 43535 | I11: 2025: público médio 28.652 (queda vs 34.501 em 2024) mas mais jogos importantes
A12: Clube Social, Esportes Olímpicos e Outras | B12: 20596 | C12: 32714 | D12: 15819 | E12: 22694 | F12: 35768 | G12: 71981 | H12: 27437 | I12: 2024 muito alto vs 2025 — provável receita não recorrente no ano anterior (Recopa?)
A14: TOTAL RECEITA BRUTA (sem deduções) | B14: =B6+B7+B8+B9+B10+B11+B12 -> 265195 | C14: =C6+C7+C8+C9+C10+C11+C12 -> 194308 | D14: =D6+D7+D8+D9+D10+D11+D12 -> 333633 | E14: =E6+E7+E8+E9+E10+E11+E12 -> 347243 | F14: =F6+F7+F8+F9+F10+F11+F12 -> 474781 | G14: =G6+G7+G8+G9+G10+G11+G12 -> 684176 | H14: =H6+H7+H8+H9+H10+H11+H12 -> 1022443 | I14: Match com relatório de gestão: 333.633 (2021), 347.243 (2022), 474.781 (2023), 684.176 (2024), 1.022.443 (2025)
A16: DECOMPOSIÇÃO PARA ANÁLISE DE RECORRÊNCIA
A17: Premiação FIFA Mundial 2025 (não recorrente, estimado) | B17: 0 | C17: 0 | D17: 0 | E17: 0 | F17: 0 | G17: 0 | H17: 331120 | I17: Fonte: globoesporte 11/07/2025 — R$ 104,56M fase grupos + R$ 226,56M mata-mata; pago entre set-out/2025
A18: Premiação recorrente (Brasileiro + Carioca + Copa BR + Sul-Am) | B18: =B8-B17 -> 27933 | C18: =C8-C17 -> 18287 | D18: =D8-D17 -> 81079 | E18: =E8-E17 -> 68290 | F18: =F8-F17 -> 188111 | G18: =G8-G17 -> 68411 | H18: =H8-H17 -> 32785 | I18: Premiação por Performance MENOS FIFA Mundial
A20: RECEITA RECORRENTE — SEM TRANSFERÊNCIAS DE JOGADORES | B20: =B14-B6 -> 159780 | C20: =C14-C6 -> 143975 | D20: =D14-D6 -> 224040 | E20: =E14-E6 -> 253313 | F20: =F14-F6 -> 458675 | G20: =G14-G6 -> 416007 | H20: =H14-H6 -> 789065 | I20: Total bruto MENOS Cessão de Atletas (linha 6)
A21: Receita recorrente reportada (relatório de gestão) | E21: 253312 | F21: 458713 | G21: 416007 | H21: 789065 | I21: Conferência contra relatório PDF 2025
A22: Diferença (calc − reportado) | I22: Diferenças de R$ 1-38 em 2022/2023 são apenas arredondamento do PDF. 2024 e 2025 fecham na unidade.
A24: RECEITA OPERACIONAL PURA (Nossa metodologia: Total − Cessão − FIFA Mundial) | B24: =B14-B6-B17 -> 159780 | C24: =C14-C6-C17 -> 143975 | D24: =D14-D6-D17 -> 224040 | E24: =E14-E6-E17 -> 253313 | F24: =F14-F6-F17 -> 458675 | G24: =G14-G6-G17 -> 416007 | H24: =H14-H6-H17 -> 457945 | I24: Total bruto MENOS Cessão MENOS Premiação Mundial
A25: Receita Recorrente PURA (Clube: Total − Cessão − TODA Premiação) | E25: 185022 | F25: 270602 | G25: 347596 | H25: 425160 | I25: O clube subtrai 100% da Premiação por Performance (incluindo Libertadores 2023). Nossa métrica é mais limpa: só remove FIFA Mundial 2025 (não recorrente verdadeiro), mantendo premiação recorrente do calendário
A26: Diferença metodológica (calc − clube) | B26: =IFERROR(B24-B25,0) -> 159780 | C26: =IFERROR(C24-C25,0) -> 143975 | D26: =IFERROR(D24-D25,0) -> 224040 | E26: =IFERROR(E24-E25,0) -> 68291 | F26: =IFERROR(F24-F25,0) -> 188073 | G26: =IFERROR(G24-G25,0) -> 68411 | H26: =IFERROR(H24-H25,0) -> 32785 | I26: Em 2025 = 32,785 ≈ Premiação recorrente do calendário (Brasileiro + Carioca + Copa BR + Sul-Am). Confirma que clube despreza essa premiação no "recorrente"
A28: CRESCIMENTO ANUAL
A29: Crescimento Receita Total (% YoY) | C29: =IFERROR((C14/B14)-1,0) -> -0.26730142 | D29: =IFERROR((D14/C14)-1,0) -> 0.71703172 | E29: =IFERROR((E14/D14)-1,0) -> 0.040793327 | F29: =IFERROR((F14/E14)-1,0) -> 0.36728746 | G29: =IFERROR((G14/F14)-1,0) -> 0.44103492 | H29: =IFERROR((H14/G14)-1,0) -> 0.49441518
A30: Crescimento Receita Recorrente Pura (% YoY) | C30: =IFERROR((C24/B24)-1,0) -> -0.098917261 | D30: =IFERROR((D24/C24)-1,0) -> 0.55610349 | E30: =IFERROR((E24/D24)-1,0) -> 0.1306597 | F30: =IFERROR((F24/E24)-1,0) -> 0.81070454 | G30: =IFERROR((G24/F24)-1,0) -> -0.093024473 | H30: =IFERROR((H24/G24)-1,0) -> 0.1008108 | I30: Métrica mais limpa para projeção
A32: MIX DE RECEITA 2025 (% sobre Total Bruto)
A33: % Cessão de Atletas | B33: =IFERROR(B6/B14,0) -> 0.39749995 | C33: =IFERROR(C6/C14,0) -> 0.2590372 | D33: =IFERROR(D6/D14,0) -> 0.32848369 | E33: =IFERROR(E6/E14,0) -> 0.27050221 | F33: =IFERROR(F6/F14,0) -> 0.033923009 | G33: =IFERROR(G6/G14,0) -> 0.39195909 | H33: =IFERROR(H6/H14,0) -> 0.22825527
A34: % Direitos de Transmissão | B34: =IFERROR(B7/B14,0) -> 0.30229454 | C34: =IFERROR(C7/C14,0) -> 0.35740165 | D34: =IFERROR(D7/D14,0) -> 0.28691107 | E34: =IFERROR(E7/E14,0) -> 0.23940583 | F34: =IFERROR(F7/F14,0) -> 0.18771181 | G34: =IFERROR(G7/G14,0) -> 0.14365456 | H34: =IFERROR(H7/H14,0) -> 0.15881081
A35: % Premiação por Performance | B35: =IFERROR(B8/B14,0) -> 0.10533004 | C35: =IFERROR(C8/C14,0) -> 0.094113469 | D35: =IFERROR(D8/D14,0) -> 0.24301853 | E35: =IFERROR(E8/E14,0) -> 0.19666343 | F35: =IFERROR(F8/F14,0) -> 0.39620583 | G35: =IFERROR(G8/G14,0) -> 0.099990353 | H35: =IFERROR(H8/H14,0) -> 0.35591715
A36: % Patrocínios e Licenciamento | B36: =IFERROR(B9/B14,0) -> 0.035264617 | C36: =IFERROR(C9/C14,0) -> 0.050275851 | D36: =IFERROR(D9/D14,0) -> 0.060251834 | E36: =IFERROR(E9/E14,0) -> 0.09374415 | F36: =IFERROR(F9/F14,0) -> 0.10453241 | G36: =IFERROR(G9/G14,0) -> 0.11440623 | H36: =IFERROR(H9/H14,0) -> 0.12922872
A37: % Sócio Futebol | B37: =IFERROR(B10/B14,0) -> 0.020166293 | C37: =IFERROR(C10/C14,0) -> 0.054315828 | D37: =IFERROR(D10/D14,0) -> 0.02626239 | E37: =IFERROR(E10/E14,0) -> 0.064142402 | F37: =IFERROR(F10/F14,0) -> 0.11959409 | G37: =IFERROR(G10/G14,0) -> 0.10211408 | H37: =IFERROR(H10/H14,0) -> 0.058373914
A38: % Bilheteria | B38: =IFERROR(B11/B14,0) -> 0.061780954 | C38: =IFERROR(C11/C14,0) -> 0.016494432 | D38: =IFERROR(D11/D14,0) -> 0.0076581154 | E38: =IFERROR(E11/E14,0) -> 0.07018716 | F38: =IFERROR(F11/F14,0) -> 0.082697075 | G38: =IFERROR(G11/G14,0) -> 0.042667384 | H38: =IFERROR(H11/H14,0) -> 0.042579391
A39: % Clube Social/Olímpicos/Outras | B39: =IFERROR(B12/B14,0) -> 0.077663606 | C39: =IFERROR(C12/C14,0) -> 0.16836157 | D39: =IFERROR(D12/D14,0) -> 0.047414374 | E39: =IFERROR(E12/E14,0) -> 0.065354809 | F39: =IFERROR(F12/F14,0) -> 0.075335786 | G39: =IFERROR(G12/G14,0) -> 0.10520831 | H39: =IFERROR(H12/H14,0) -> 0.026834748

Sheet DFC
A1: FLUMINENSE FOOTBALL CLUB — Demonstração dos Fluxos de Caixa (DFC)
A2: Em milhares de Reais | Método indireto conforme PDFs | 2023 reap + 2024 + 2025
B4: 2023 reap | C4: 2024 | D4: 2025 | E4: Notas
A5: FLUXO DE CAIXA DAS ATIVIDADES OPERACIONAIS
A6: Superávit do exercício | B6: 78721 | C6: 114 | D6: 51585
A7: Itens que não afetam o caixa:
A8: Amortização dos direitos econômicos de atletas | B8: 18540 | C8: 14511 | D8: 84225 | E8: Salto refletindo amortização das 11 contratações de 2025
A9: Depreciação e amortização de outros ativos | B9: 4112 | C9: 4444 | D9: 6762
A10: Constituição (reversão) da provisão para contingência | B10: -9520 | C10: 2377 | D10: 30861 | E10: Auditor 2025 aponta déficit de R$ 34.176 adicional
A11: Despesas financeiras de juros de empréstimos | B11: 7820 | C11: 12210 | D11: 5519
A12: Despesas financeiras de juros de impostos a pagar | B12: 21850 | C12: 43120 | D12: 139258 | E12: Atualização Selic dos parcelamentos tributários
A13: Descontos obtidos | B13: -3120 | C13: -3058 | D13: -90891 | E13: 2025: desconto PGFN R$ 89.766 da nova transação de nov/2025
A14: Amortização da receita diferida/adiantamentos | B14: 0 | C14: -9583 | D14: 0
A15: Ajustes da adoção da ITG 2003 (R2) | B15: 0 | C15: -48530 | D15: 0 | E15: Baixa de "Atletas em Formação" contra patrimônio
A16: Ganho com transferências de atletas, líquido do custo | B16: 0 | C16: 344359 | D16: 335568
A17: Equivalência patrimonial | B17: 0 | C17: 0 | D17: -7505 | E17: Lucro Fla-Flu Serviços S.A.
A18: Superávit ajustado | B18: =SUM(B6:B17) -> 118403 | C18: =SUM(C6:C17) -> 359964 | D18: =SUM(D6:D17) -> 555382 | E18: Soma das linhas acima
A20: VARIAÇÃO NAS CONTAS DE CAPITAL DE GIRO
A21: Contas a receber | B21: 60000 | C21: 21623 | D21: 45503 | E21: 2025: realização da LFU/LFF
A22: Contas a receber na transferência de jogadores | B22: -150000 | C22: -422388 | D22: -329249 | E22: Reflete reconhecimento das vendas Kauã/Arias/Isaque com parcelamento
A23: Adiantamentos a fornecedores | B23: 10000 | C23: 13185 | D23: -11584
A24: Depósitos judiciais | B24: 5000 | C24: 1938 | D24: 390
A25: Outros ativos | B25: 1500 | C25: 1326 | D25: 3239
A26: Fornecedores | B26: 2000 | C26: 562 | D26: 24141
A27: Contas a pagar transferência de jogadores | B27: 8000 | C27: 41291 | D27: 144578 | E27: Parcelamento das 11 contratações 2025
A28: Direito de imagem a pagar | B28: -5000 | C28: -6352 | D28: 4277
A29: Impostos e contribuições a pagar | B29: 18000 | C29: 18609 | D29: -6474
A30: Obrigações trabalhistas e sociais | B30: 10000 | C30: 5698 | D30: -5755
A31: Contas a pagar acordos judiciais | B31: 15000 | C31: 19542 | D31: -75763 | E31: 2025: leilões TRT com deságio 30%
A32: Provisões para contingências | B32: -8000 | C32: -13626 | D32: -12035
A33: Adiantamentos recebidos | B33: -10000 | C33: -15536 | D33: -4315
A34: Outros passivos | B34: 5000 | C34: 10172 | D34: -6298
A35: Juros pagos referente a empréstimos | B35: -500 | C35: -416 | D35: -2604
A36: Juros pagos referente a impostos | B36: -15000 | C36: -13268 | D36: -9755
A37: Caixa líquido das atividades operacionais | B37: =B18+SUM(B21:B36) -> 64403 | C37: =C18+SUM(C21:C36) -> 22324 | D37: =D18+SUM(D21:D36) -> 313678
A39: FLUXO DE CAIXA DAS ATIVIDADES DE INVESTIMENTOS
A40: Investimento em direitos econômicos de atletas profissionais | B40: -32000 | C40: -72558 | D40: -317215 | E40: CONTRADIÇÃO Nota 8 vs DFC: Nota mostra R$ 215.151 de adições; diferença R$ 102.064 = pagamentos de contraprestações variáveis e parcelas antigas
A41: Baixa intangível (alienação de jogadores) | B41: 50000 | C41: 72358 | D41: 102190
A42: Investimento em outros intangíveis | B42: 0 | C42: -5509 | D42: -110540 | E42: 2025: recompra parcial FFU (R$ 110.427) — base da ressalva do auditor
A43: Compras de imobilizado | B43: -3000 | C43: -4161 | D43: -4699
...

Sheet Operacional_Puro
A1: FLUMINENSE FOOTBALL CLUB — Análise Operacional Pura (Recorrente)
A2: TESE CENTRAL: descontar eventos não recorrentes (FIFA Mundial 2025, descontos PGFN, cessão de atletas) revela que a operação dia-a-dia do Fluminense permanece estruturalmente deficitária
B4: 2023 reap | C4: 2024 | D4: 2025 | E4: Notas
A5: PONTO DE PARTIDA — EBITDA REPORTADO
A6: EBITDA reportado (calculado a partir da DRE) | B6: =DRE!C36 -> 86438 | C6: =DRE!D36 -> 105844 | D6: =DRE!E36 -> 191485 | E6: Vem da aba DRE: EBIT + Depreciação + Amortização atletas
A7: EBITDA divulgado pela gestão | B7: 146866 | C7: 105844 | D7: 191485 | E7: Conforme relatório de gestão PDF — pode divergir do calculado por classificações
A9: DESCONTAR EVENTOS NÃO RECORRENTES DE RECEITA
A10: (−) Cessão de direitos econômicos (volátil ano a ano) | B10: =-DRE!C20 -> -16106 | C10: =-DRE!D20 -> -268169 | D10: =-DRE!E20 -> -233378 | E10: Conceitualmente uma "venda de ativo" não recorrente. Em 2024: R$ 268M (Wolverhampton/André). Em 2025: R$ 233M (3 atletas).
A11: (+) Custo de cessão (volta para neutralizar) | B11: =-DRE!C21 -> 2185 | C11: =-DRE!D21 -> 5720 | D11: =-DRE!E21 -> 6255 | E11: Sinal invertido (era negativo na DRE)
A12: (−) Premiação FIFA Mundial 2025 (não recorrente) | B12: 0 | C12: 0 | D12: -331120 | E12: R$ 104,56M fase grupos + R$ 226,56M mata-mata; pago set-out/2025. Sujeito a 30-35% de retenção americana via modelo ECI
A13: (−) Premiação Libertadores 2023 (não recorrente nesse exercício) | B13: -136000 | C13: 0 | D13: 0 | E13: OFICIAL CONMEBOL: USD 27,15M total (USD 3M grupos + USD 0,9M 3 vitórias + USD 1,25M oitavas + USD 1,7M quartas + USD 2,3M semi + USD 18M campeão). Conversão à taxa média 2023 (USD/BRL ~5,01) = R$ 136M. Fonte: ge.globo.com
A14: (−) Recopa 2024 (não recorrente) | B14: 0 | C14: -8900 | D14: 0 | E14: OFICIAL CONMEBOL: USD 1,8M premiação campeão (USD 0,9M vice). Conversão à taxa média 2024 (~R$ 4,94) = R$ 8,9M. Fonte: ge.globo.com
A15: Total descontos de receita não recorrente | B15: =B10+B11+B12+B13+B14 -> -149921 | C15: =C10+C11+C12+C13+C14 -> -271349 | D15: =D10+D11+D12+D13+D14 -> -558243 | E15: Soma dos descontos acima
A17: DESCONTAR EVENTOS NÃO RECORRENTES DO RESULTADO FINANCEIRO
A18: (−) Descontos PGFN não recorrentes (estavam em Receitas Financeiras) | B18: -3120 | C18: -3058 | D18: -90891 | E18: 2025: nova transação PGFN nov/2025 com desconto R$ 89.766. Esses descontos não voltam todo ano.
A19: Esses descontos NÃO entram no EBITDA (estão abaixo da linha) — mas SE entrassem, seriam não recorrentes | E19: Item informativo — não soma no EBITDA recorrente
A21: AJUSTES PARA EVENTOS NÃO RECORRENTES DE CUSTO
A22: (+) Prêmios e gratificações extraordinárias FIFA Mundial | B22: 0 | C22: 0 | D22: 82010 | E22: Estimativa: dos R$ 98.894 totais de prêmios em 2025 (Nota 18), ~R$ 82M atribuíveis ao Mundial — diferença vs R$ 16,9M em 2024
A23: (+) Comissões extras na venda de atletas (não recorrente) | B23: 0 | C23: 0 | D23: 28854 | E23: Diferença das comissões de vendas: R$ 52,1M (2025) vs R$ 23,2M (2024); o excesso é proporcional ao volume vendido
A24: Total acréscimos de custo não recorrente | B24: =B22+B23 -> 0 | C24: =C22+C23 -> 0 | D24: =D22+D23 -> 110864
A26: EBITDA RECORRENTE PURO | B26: =B6+B15+B24 -> -63483 | C26: =C6+C15+C24 -> -165505 | D26: =D6+D15+D24 -> -255894 | E26: EBITDA reportado − Receitas não rec + Custos não rec
A27: Receita operacional líquida recorrente | B27: =DRE!C5+B15 -> 308792 | C27: =DRE!D5+C15 -> 128275 | D27: =DRE!E5+D15 -> 200303 | E27: Receita líquida − Cessão líquida − FIFA − Premiação extra
A28: Margem EBITDA Recorrente | B28: =IFERROR(B26/B27,0) -> -0.20558499 | C28: =IFERROR(C26/C27,0) -> -1.2902358 | D28: =IFERROR(D26/D27,0) -> -1.2775345
A30: CONCLUSÃO ANALÍTICA
A31: EBITDA reportado pela gestão (de novo) | B31: =DRE!C37 -> 146866 | C31: =DRE!D37 -> 105844 | D31: =DRE!E37 -> 191485
A32: EBITDA Recorrente Puro (linha acima) | B32: =B26 -> -63483 | C32: =C26 -> -165505 | D32: =D26 -> -255894 | E32: Repetido para comparação direta
A33: GAP: % do EBITDA divulgado que vem de eventos não recorrentes | B33: =IFERROR(1-B26/B31,0) -> 1.4322512 | C33: =IFERROR(1-C26/C31,0) -> 2.5636692 | D33: =IFERROR(1-D26/D31,0) -> 2.3363658 | E33: Quanto maior, mais frágil é a operação dia-a-dia
A35: CONTEXTO: A OPERAÇÃO RECORRENTE PRECISA COBRIR
A36: Custo recorrente com folha + benefícios (estimado) | B36: -297820 | C36: -371159 | D36: -439653 | E36: 2025: removidos os ~R$ 82M de prêmios FIFA extras
A37: Custo recorrente com viagens e jogos | B37: -56178 | C37: -71975 | D37: -88419 | E37: Item integralmente recorrente
A38: Comissões/serviços terceiros recorrentes | B38: -36529 | C38: -44118 | D38: -60087 | E38: 2025: removidas as comissões extras de vendas (R$ 28,9M)
A39: Gastos gerais | B39: -42375 | C39: -52295 | D39: -54138
A40: Total custos recorrentes mínimos | B40: =B36+B37+B38+B39 -> -432902 | C40: =C36+C37+C38+C39 -> -539547 | D40: =D36+D37+D38+D39 -> -642297 | E40: Custos que sobrevivem mesmo num "ano sem eventos"
A42: Receita operacional líquida recorrente (de novo) | B42: =B27 -> 308792 | C42: =C27 -> 128275 | D42: =D27 -> 200303
A43: Resultado operacional recorrente — antes de cessão e premiações extras | B43: =B42+B40 -> -124110 | C43: =C42+C40 -> -411272 | D43: =D42+D40 -> -441994 | E43: É o "lucro do dia-a-dia" antes de qualquer evento extraordinário

Sheet Indicadores
A1: FLUMINENSE FOOTBALL CLUB — Painel de Indicadores
A2: Indicadores derivados das DFs. Em vermelho: indicadores que sinalizam vulnerabilidade.
B4: 2022 (R1) | C4: 2023 reap | D4: 2024 | E4: 2025 | F4: Análise
A5: LIQUIDEZ E SOLVÊNCIA
A6: Liquidez Corrente (AC / PC) | B6: =BP!B12/BP!B37 -> 0.22003827 | C6: =BP!C12/BP!C37 -> 0.61572096 | D6: =BP!D12/BP!D37 -> 0.45608666 | E6: =BP!E12/BP!E37 -> 0.37428924 | F6: Bom: >1. Crítico abaixo de 0,5. Flu opera estruturalmente abaixo de 0,5
A7: Capital Circulante Líquido (R$ mil) | B7: =BP!B12-BP!B37 -> -228645 | C7: =BP!C12-BP!C37 -> -127347 | D7: =BP!D12-BP!D37 -> -212935 | E7: =BP!E12-BP!E37 -> -302727 | F7: Negativo significa que dívidas de curto prazo > ativos de curto prazo. Auditor cita R$ -309M em 2025
A8: Passivo a Descoberto (PL negativo, R$ mil) | B8: =BP!B57 -> -263936 | C8: =BP!C57 -> -185215 | D8: =BP!D57 -> -233630 | E8: =BP!E57 -> -182045 | F8: Redução de R$ 233M (2024) para R$ 182M (2025) — melhora estrutural
A10: ALAVANCAGEM
A11: Dívida Total / Receita Líquida | B11: =BP!B48/DRE!B5 -> 2.4191313 | C11: =BP!C48/DRE!C5 -> 1.7941327 | D11: =BP!D48/DRE!D5 -> 2.1663138 | E11: =BP!E48/DRE!E5 -> 1.3748883 | F11: Útil para comparar com tese do relatório de gestão (receitas cresceram 285%, dívida só 20%)
A12: Dívida Total / EBITDA reportado | B12: =IFERROR(BP!B48/DRE!B36,0) -> 8.826161 | C12: =IFERROR(BP!C48/DRE!C36,0) -> 9.5211828 | D12: =IFERROR(BP!D48/DRE!D36,0) -> 8.1791221 | E12: =IFERROR(BP!E48/DRE!E36,0) -> 5.4464632 | F12: Acima de 5x é alavancagem crítica. Flu opera entre 5x e 12x
A13: Dívida Total / EBITDA Recorrente Puro | B13: N/A | C13: =IFERROR(BP!C48/Operacional_Puro!B26,0) -> -12.963975 | D13: =IFERROR(BP!D48/Operacional_Puro!C26,0) -> -5.2307241 | E13: =IFERROR(BP!E48/Operacional_Puro!D26,0) -> -4.0755782 | F13: Como o EBITDA recorrente é negativo, o indicador é negativo (pior interpretação: dívida não tem como ser amortizada com a operação)
A14: Tributos parcelados / Dívida Total | B14: =(BP!B29+BP!B42)/BP!B48 -> 0.39596477 | C14: =(BP!C29+BP!C42)/BP!C48 -> 0.45761077 | D14: =(BP!D29+BP!D42)/BP!D48 -> 0.45314083 | E14: =(BP!E29+BP!E42)/BP!E48 -> 0.45064032 | F14: Acima de 45% confirma natureza fiscal da dívida (sujeita à Selic)
A16: DEPENDÊNCIA DE EVENTOS NÃO RECORRENTES
A17: Receita de Cessão / Receita Total Bruta | B17: =Receita_Detalhada!E6/Receita_Detalhada!E14 -> 0.27050221 | C17: =Receita_Detalhada!F6/Receita_Detalhada!F14 -> 0.033923009 | D17: =Receita_Detalhada!G6/Receita_Detalhada!G14 -> 0.39195909 | E17: =Receita_Detalhada!H6/Receita_Detalhada!H14 -> 0.22825527 | F17: Acima de 25% sinaliza dependência estrutural de venda de atletas. 2024 (LFU?): 39%
A18: Receita de Premiação / Receita Total Bruta | B18: =Receita_Detalhada!E8/Receita_Detalhada!E14 -> 0.19666343 | C18: =Receita_Detalhada!F8/Receita_Detalhada!F14 -> 0.39620583 | D18: =Receita_Detalhada!G8/Receita_Detalhada!G14 -> 0.099990353 | E18: =Receita_Detalhada!H8/Receita_Detalhada!H14 -> 0.35591715 | F18: 2025: 36% por causa do Mundial — fortemente concentrado em evento único
A19: Receita "do dia-a-dia" / Receita Total (sócio + bilheteria + patrocínio) | B19: =(Receita_Detalhada!E9+Receita_Detalhada!E10+Receita_Detalhada!E11)/Receita_Detalhada!E14 -> 0.22807371 | C19: =(Receita_Detalhada!F9+Receita_Detalhada!F10+Receita_Detalhada!F11)/Receita_Detalhada!F14 -> 0.30682357 | D19: =(Receita_Detalhada!G9+Receita_Detalhada!G10+Receita_Detalhada!G11)/Receita_Detalhada!G14 -> 0.25918769 | E19: =(Receita_Detalhada!H9+Receita_Detalhada!H10+Receita_Detalhada!H11)/Receita_Detalhada!H14 -> 0.23018202 | F19: Indica quão "dia-a-dia" é a operação. Quanto menor, mais dependente de eventos extraordinários
A21: CONCENTRAÇÃO DE VENDAS
A22: % do total de cessões dos 3 maiores ativos vendidos (2025) | B22: N/A | C22: N/A | D22: =(132037+56190+17181)/268169 -> 0.76596475 | E22: =(78727+60509+55198)/233378 -> 0.83312909 | F22: 2024 = 76% Wolverhampton+Al Ahli+Zenit | 2025 = 83% Kauã Elias+Arias+Isaque
A24: RENTABILIDADE
A25: Margem EBITDA reportada | B25: =DRE!B38 -> 0.27408647 | C25: =DRE!C38 -> 0.18843591 | D25: =DRE!D38 -> 0.26485897 | E25: =DRE!E38 -> 0.2524369 | F25: Olhando isolado, parece saudável (~25%). Mas EBITDA reportado inclui R$ 233M de cessão e R$ 331M de FIFA em 2025
A26: Margem EBITDA Recorrente Pura | B26: N/A | C26: =Operacional_Puro!B28 -> -0.20558499 | D26: =Operacional_Puro!C28 -> -1.2902358 | E26: =Operacional_Puro!D28 -> -1.2775345 | F26: Revelador: operação dia-a-dia tem margem operacional NEGATIVA estruturalmente
A27: Superávit do Exercício / Receita Líquida | B27: =DRE!B40 -> 0.091360125 | C27: =DRE!C40 -> 0.052594978 | D27: =DRE!D40 -> 0.00028526815 | E27: =DRE!E40 -> 0.068005105 | F27: "Superávit pelo 4º ano consecutivo" (gestão) é tecnicamente verdade, mas marginal e dependente de cessões
A29: FLUXO DE CAIXA QUALITATIVO
A30: Caixa final / Compromissos circulantes (cobertura) | B30: =BP!B7/BP!B37 -> 0.00017397296 | C30: =BP!C7/BP!C37 -> 0.12591433 | D30: =BP!D7/BP!D37 -> 0.026624128 | E30: =BP!E7/BP!E37 -> 0.071362283 | F30: R$ 34M de caixa cobre apenas 7% dos R$ 484M de passivo circulante (2025). Posição extremamente apertada
A31: Caixa final em meses de folha (R$ mil) | B31: =BP!B7/(-DRE!B8/12) -> 0.0029165773 | C31: =BP!C7/(-DRE!C8/12) -> 1.9421457 | D31: =BP!D7/(-DRE!D8/12) -> 0.33698765 | E31: =BP!E7/(-DRE!E8/12) -> 0.79421389 | F31: Quantos meses de folha o caixa cobre. Em 2025: ~0,8 meses
A33: ATIVOS — VALORIZAÇÃO DE ELENCO
A34: Intangível (R$ mil) — direitos econômicos de atletas | B34: =BP!B18 -> 78054 | C34: =BP!C18 -> 79860 | D34: =BP!D18 -> 65506 | E34: =BP!E18 -> 306803 | F34: 2025: R$ 307M (inclui R$ 110M de Direito de Uso de Marca — recompra FFU, ressalva auditor)
A35: Contas a pagar transferências (passivo total) | B35: =BP!B27+BP!B40 -> 51501 | C35: =BP!C27+BP!C40 -> 58323 | D35: =BP!D27+BP!D40 -> 99613 | E35: =BP!E27+BP!E40 -> 244192 | F35: 2025: R$ 244M (vs R$ 99M em 2024) — explosão por causa das 11 contratações
A36: Investimento líquido em elenco (Intangível − Contas a pagar) | B36: =BP!B18-(BP!B27+BP!B40) -> 26553 | C36: =BP!C18-(BP!C27+BP!C40) -> 21537 | D36: =BP!D18-(BP!D27+BP!D40) -> -34107 | E36: =BP!E18-(BP!E27+BP!E40) -> 62611 | F36: Quanto efetivamente é patrimônio próprio. Negativo significa que o elenco custa mais do que vale no balanço

Sheet Premissas_Runway
A1: FLUMINENSE FOOTBALL CLUB — Premissas dos Cenários 2026-2027
A2: Painel de controle editável. Todos os valores em AZUL podem ser alterados. O Modelo_Runway recalcula automaticamente.
B4: Pessimista | C4: Base | D4: Otimista | E4: Justificativa / Fonte
A5: CÂMBIO E MACRO
A6: USD/BRL médio 2026 | B6: 5.2 | C6: 5.05 | D6: 4.9 | E6: Faixa: 5,00-5,05 atual (mai/2026). Cenário pessimista assume depreciação para 5,20
A7: EUR/BRL médio 2026 | B7: 6 | C7: 5.82 | D7: 5.65 | E7: Faixa: 5,80-5,85 atual
A8: USD/BRL médio 2027 | B8: 5.4 | C8: 5.1 | D8: 4.8 | E8: Pessimista projeta depreciação contínua; otimista assume estabilidade
A9: EUR/BRL médio 2027 | B9: 6.2 | C9: 5.85 | D9: 5.55
A10: SELIC média 2026 | B10: 0.135 | C10: 0.115 | D10: 0.1 | E10: Pessimista: BCB mantém juros altos | Base: queda gradual | Otimista: queda mais rápida
A11: Inflação IPCA 2026 (custos) | B11: 0.06 | C11: 0.045 | D11: 0.035
A13: RECEITAS RECORRENTES
A14: Crescimento receita recorrente 2026 (% YoY sobre 2025) | B14: 0.03 | C14: 0.06 | D14: 0.1 | E14: Base: média histórica 2019-2025 ~6% real. Pessimista assume estagnação por queda em campo; Otimista assume aproveitamento da exposição da Copa do Mundo
A15: Crescimento receita recorrente 2027 (% YoY sobre 2026) | B15: 0.02 | C15: 0.05 | D15: 0.09
A17: PREMIAÇÃO CONMEBOL 2026
A18: Premiação CONMEBOL 2026 (R$ mil) | B18: =B22 -> 41600 | C18: =C22 -> 27775 | D18: =D22 -> 36750 | E18: Valores agregados — desagregados nas linhas abaixo. Câmbio USD/BRL 2026.
A19: Pessimista: Grupos Libertadores + final Sul-Americana (USD mi) | B19: 8 | E19: USD 3M grupos + USD ~1M vitórias + USD 0,5M oitavas Sul-Am + USD 0,9M quartas + USD 1,55M semi + USD 2,1M vice-campeão Sul-Am ~ USD 8M
A20: Base: Oitavas Libertadores + algumas vitórias grupo (USD mi) | C20: 5.5 | E20: USD 3M grupos + USD ~1,25M (4 vitórias) + USD 1,25M oitavas ~ USD 5,5M
A21: Otimista: Quartas Libertadores (USD mi) | D21: 7.5 | E21: USD 3M grupos + USD 1,7M (5 vitórias) + USD 1,25M oitavas + USD 1,7M quartas ~ USD 7,65M
A22: Conversão para R$ mil | B22: =ROUND(B19*B6*1000,0) -> 41600 | C22: =ROUND(C20*C6*1000,0) -> 27775 | D22: =ROUND(D21*D6*1000,0) -> 36750 | E22: USD mi × câmbio × 1000 = R$ mil
A24: PREMIAÇÃO 2027 (premissas conservadoras)
A25: Premiação CONMEBOL 2027 (USD mi) | B25: 3 | C25: 5 | D25: 7 | E25: Sem certeza de classificação. Pessimista: grupos só | Base: oitavas Libertadores | Otimista: quartas
A26: Conversão CONMEBOL 2027 para R$ mil | B26: =ROUND(B25*B8*1000,0) -> 16200 | C26: =ROUND(C25*C8*1000,0) -> 25500 | D26: =ROUND(D25*D8*1000,0) -> 33600
A28: VENDA DE ATLETAS
A29: Receita de cessão 2026 (R$ mil) | B29: 70000 | C29: 130000 | D29: 218000 | E29: Pessimista: mercado fraco, sem ativos visados | Base: média histórica 4 anos | Otimista: premissa do clube no Relatório de Gestão
A30: Receita de cessão 2027 (R$ mil) | B30: 60000 | C30: 110000 | D30: 180000 | E30: Tendência de declínio sem renovação do elenco com ativos visados
A31: Custo de cessão / Receita de cessão (%) | B31: 0.04 | C31: 0.03 | D31: 0.025 | E31: Histórico 2024-2025: 2-3% — comissões + baixa de intangível
A33: CAPEX EM ATLETAS (COMPROMETIMENTO)
A34: Capex comprometido 2026 (R$ mil) — VALOR DO CONTRATO | B34: 162000 | C34: 180000 | D34: 250000 | E34: 5 contratações confirmadas R$ 158M (Castillo R$ 67,9M + Savarino R$ 22,6M + Arana R$ 20,1M + Millán R$ 25,1M + Jemmes R$ 22M)
A35: Capex comprometido 2027 (R$ mil) | B35: 80000 | C35: 120000 | D35: 200000 | E35: Janela menos previsível — projetar com base no ritmo histórico
A36: % do Capex que vira saída de caixa no mesmo ano | B36: 0.5 | C36: 0.55 | D36: 0.6 | E36: Padrão Flu 2025: comprometeu R$ 215M mas pagou R$ 317M (50% do ano + parcelas antigas). Maior % otimista assume mais à vista
A37: Amortização de parcelas de Capex antigo em 2026 (R$ mil) | B37: 150000 | C37: 130000 | D37: 110000 | E37: Estimado a partir do BP 2025: R$ 244M de contas a pagar transferências (196M circ + 48M NC). Pessimista paga mais (acelera obrigações), Otimista renegocia
A38: Amortização de parcelas de Capex antigo em 2027 (R$ mil) | B38: 130000 | C38: 110000 | D38: 90000
A40: AMORTIZAÇÃO DE INTANGÍVEL (DRE — não caixa)
A41: Amortização atletas 2026 (R$ mil) | B41: 100000 | C41: 95000 | D41: 90000 | E41: 2025: R$ 84,2M com elenco menor. 2026 sobe pelo capex de R$ 158M+ adicionado. Pessimista assume amortização integral; Otimista assume vidas úteis mais longas (5 anos)
A42: Amortização atletas 2027 (R$ mil) | B42: 105000 | C42: 100000 | D42: 95000
A44: CUSTOS RECORRENTES (CRESCIMENTO REAL)
A45: Crescimento folha + benefícios 2026 (% YoY) | B45: 0.08 | C45: 0.04 | D45: 0.02 | E45: Pessimista: pressão sindical + 5 contratações sêniores | Base: alinhado à inflação | Otimista: redução real com saída de atletas caros
A46: Crescimento folha 2027 (% YoY) | B46: 0.06 | C46: 0.04 | D46: 0.02
A47: Crescimento outros custos operacionais (% YoY) | B47: 0.06 | C47: 0.045 | D47: 0.03 | E47: IPCA + ajuste real
A49: DÍVIDA E FINANCEIRO
...

Sheet Modelo_Runway
A1: FLUMINENSE FOOTBALL CLUB — Modelo Runway 2026-2027 (3 Cenários)
A2: Projeção integrada DRE → Geração de caixa → Posição final. Todas as premissas pluxam da aba Premissas_Runway.
B3: PESSIMISTA | D3: BASE | F3: OTIMISTA
B4: 2026 | C4: 2027 | D4: 2026 | E4: 2027 | F4: 2026 | G4: 2027 | H4: Notas
A5: RECEITA OPERACIONAL
A6: Receita recorrente (sem cessão sem FIFA) | B6: =ROUND(425160*(1+Premissas_Runway!B14),0) -> 437915 | C6: =ROUND(B6*(1+Premissas_Runway!B15),0) -> 446673 | D6: =ROUND(425160*(1+Premissas_Runway!C14),0) -> 450670 | E6: =ROUND(D6*(1+Premissas_Runway!C15),0) -> 473204 | F6: =ROUND(425160*(1+Premissas_Runway!D14),0) -> 467676 | G6: =ROUND(F6*(1+Premissas_Runway!D15),0) -> 509767 | H6: Cresce sobre R$ 425M de 2025 (Receita Recorrente Pura reportada)
A7: Receita de cessão de atletas | B7: =Premissas_Runway!B29 -> 70000 | C7: =Premissas_Runway!B30 -> 60000 | D7: =Premissas_Runway!C29 -> 130000 | E7: =Premissas_Runway!C30 -> 110000 | F7: =Premissas_Runway!D29 -> 218000 | G7: =Premissas_Runway!D30 -> 180000 | H7: Vem direto da Premissas_Runway
A8: Premiação CONMEBOL | B8: =Premissas_Runway!B22 -> 41600 | C8: =Premissas_Runway!B26 -> 16200 | D8: =Premissas_Runway!C22 -> 27775 | E8: =Premissas_Runway!C26 -> 25500 | F8: =Premissas_Runway!D22 -> 36750 | G8: =Premissas_Runway!D26 -> 33600 | H8: Libertadores + Sul-Americana conforme cenário
A9: TOTAL RECEITA BRUTA | B9: =B6+B7+B8 -> 549515 | C9: =C6+C7+C8 -> 522873 | D9: =D6+D7+D8 -> 608445 | E9: =E6+E7+E8 -> 608704 | F9: =F6+F7+F8 -> 722426 | G9: =G6+G7+G8 -> 723367
A10: (−) Deduções (impostos sobre receita ~26%) | B10: =ROUND(-B9*0.26,0) -> -142874 | C10: =ROUND(-C9*0.26,0) -> -135947 | D10: =ROUND(-D9*0.26,0) -> -158196 | E10: =ROUND(-E9*0.26,0) -> -158263 | F10: =ROUND(-F9*0.26,0) -> -187831 | G10: =ROUND(-G9*0.26,0) -> -188075 | H10: Média histórica 2024-2025: ~26% de deduções (dif entre bruta e líquida)
A11: Receita Operacional Líquida | B11: =B9+B10 -> 406641 | C11: =C9+C10 -> 386926 | D11: =D9+D10 -> 450249 | E11: =E9+E10 -> 450441 | F11: =F9+F10 -> 534595 | G11: =G9+G10 -> 535292
A13: CUSTOS E DESPESAS
A14: Custo com folha + benefícios (recorrente) | B14: =ROUND(-439653*(1+Premissas_Runway!B45),0) -> -474825 | C14: =ROUND(B14*(1+Premissas_Runway!B46),0) -> -503315 | D14: =ROUND(-439653*(1+Premissas_Runway!C45),0) -> -457239 | E14: =ROUND(D14*(1+Premissas_Runway!C46),0) -> -475529 | F14: =ROUND(-439653*(1+Premissas_Runway!D45),0) -> -448446 | G14: =ROUND(F14*(1+Premissas_Runway!D46),0) -> -457415 | H14: Cresce sobre R$ 440M (folha recorrente 2025, ex-prêmios FIFA)
A15: Custos com viagens, jogos e competições | B15: =ROUND(-88419*(1+Premissas_Runway!B47),0) -> -93724 | C15: =ROUND(B15*(1+Premissas_Runway!B47),0) -> -99347 | D15: =ROUND(-88419*(1+Premissas_Runway!C47),0) -> -92398 | E15: =ROUND(D15*(1+Premissas_Runway!C47),0) -> -96556 | F15: =ROUND(-88419*(1+Premissas_Runway!D47),0) -> -91072 | G15: =ROUND(F15*(1+Premissas_Runway!D47),0) -> -93804 | H15: Cresce sobre R$ 88M de 2025
A16: Comissões e serviços terceiros (recorrente) | B16: =ROUND(-60087*(1+Premissas_Runway!B47),0) -> -63692 | C16: =ROUND(B16*(1+Premissas_Runway!B47),0) -> -67514 | D16: =ROUND(-60087*(1+Premissas_Runway!C47),0) -> -62791 | E16: =ROUND(D16*(1+Premissas_Runway!C47),0) -> -65617 | F16: =ROUND(-60087*(1+Premissas_Runway!D47),0) -> -61890 | G16: =ROUND(F16*(1+Premissas_Runway!D47),0) -> -63747 | H16: Cresce sobre R$ 60M (recorrente 2025 ex-comissões extras de venda)
A17: Custo de cessão de atletas | B17: =ROUND(-B7*Premissas_Runway!B31,0) -> -2800 | C17: =ROUND(-C7*Premissas_Runway!B31,0) -> -2400 | D17: =ROUND(-D7*Premissas_Runway!C31,0) -> -3900 | E17: =ROUND(-E7*Premissas_Runway!C31,0) -> -3300 | F17: =ROUND(-F7*Premissas_Runway!D31,0) -> -5450 | G17: =ROUND(-G7*Premissas_Runway!D31,0) -> -4500 | H17: Receita cessão × % de custo
A18: Amortização de atletas (não caixa) | B18: =-Premissas_Runway!B41 -> -100000 | C18: =-Premissas_Runway!B42 -> -105000 | D18: =-Premissas_Runway!C41 -> -95000 | E18: =-Premissas_Runway!C42 -> -100000 | F18: =-Premissas_Runway!D41 -> -90000 | G18: =-Premissas_Runway!D42 -> -95000 | H18: Vem da Premissas_Runway
A19: Outros custos operacionais | B19: =ROUND(-71062*(1+Premissas_Runway!B47),0) -> -75326 | C19: =ROUND(B19*(1+Premissas_Runway!B47),0) -> -79846 | D19: =ROUND(-71062*(1+Premissas_Runway!C47),0) -> -74260 | E19: =ROUND(D19*(1+Premissas_Runway!C47),0) -> -77602 | F19: =ROUND(-71062*(1+Premissas_Runway!D47),0) -> -73194 | G19: =ROUND(F19*(1+Premissas_Runway!D47),0) -> -75390 | H19: Cresce sobre R$ 60M de 2025 (depreciação + tributos câmbio + gastos gerais − resultado equiv. patrimonial)
A20: TOTAL CUSTOS E DESPESAS | B20: =B14+B15+B16+B17+B18+B19 -> -810367 | C20: =C14+C15+C16+C17+C18+C19 -> -857422 | D20: =D14+D15+D16+D17+D18+D19 -> -785588 | E20: =E14+E15+E16+E17+E18+E19 -> -818604 | F20: =F14+F15+F16+F17+F18+F19 -> -770052 | G20: =G14+G15+G16+G17+G18+G19 -> -789856
A22: RESULTADO OPERACIONAL
A23: EBIT (Resultado Operacional) | B23: =B11+B20 -> -403726 | C23: =C11+C20 -> -470496 | D23: =D11+D20 -> -335339 | E23: =E11+E20 -> -368163 | F23: =F11+F20 -> -235457 | G23: =G11+G20 -> -254564 | H23: Receita Líquida + Custos
A24: (+) Amortização de atletas (volta — não caixa) | B24: =-B18 -> 100000 | C24: =-C18 -> 105000 | D24: =-D18 -> 95000 | E24: =-E18 -> 100000 | F24: =-F18 -> 90000 | G24: =-G18 -> 95000 | H24: Adiciona de volta a amortização para chegar a EBITDA
A25: (+) Depreciação outros (estimado) | B25: 7000 | C25: 7000 | D25: 7000 | E25: 7000 | F25: 7000 | G25: 7000 | H25: Estima R$ 7M/ano
A26: EBITDA | B26: =B23+B24+B25 -> -296726 | C26: =C23+C24+C25 -> -358496 | D26: =D23+D24+D25 -> -233339 | E26: =E23+E24+E25 -> -261163 | F26: =F23+F24+F25 -> -138457 | G26: =G23+G24+G25 -> -152564
A27: Margem EBITDA (%) | B27: =IFERROR(B26/B11,0) -> -0.72970015 | C27: =IFERROR(C26/C11,0) -> -0.92652342 | D27: =IFERROR(D26/D11,0) -> -0.51824435 | E27: =IFERROR(E26/E11,0) -> -0.57979402 | F27: =IFERROR(F26/F11,0) -> -0.25899419 | G27: =IFERROR(G26/G11,0) -> -0.2850108
A29: RESULTADO FINANCEIRO
A30: Receitas financeiras (recorrentes) | B30: =Premissas_Runway!B52 -> 5000 | C30: =Premissas_Runway!B53 -> 5000 | D30: =Premissas_Runway!C52 -> 8000 | E30: =Premissas_Runway!C53 -> 8000 | F30: =Premissas_Runway!D52 -> 12000 | G30: =Premissas_Runway!D53 -> 12000 | H30: Vem da Premissas_Runway
A31: Despesas financeiras | B31: =-ROUND(BP!E48*Premissas_Runway!B50,0) -> -156437 | C31: =-ROUND(BP!E48*Premissas_Runway!B51,0) -> -146008 | D31: =-ROUND(BP!E48*Premissas_Runway!C50,0) -> -135579 | E31: =-ROUND(BP!E48*Premissas_Runway!C51,0) -> -125150 | F31: =-ROUND(BP!E48*Premissas_Runway!D50,0) -> -114721 | G31: =-ROUND(BP!E48*Premissas_Runway!D51,0) -> -104292 | H31: % Dívida total estimada × dívida ano anterior
A32: Resultado financeiro líquido | B32: =B30+B31 -> -151437 | C32: =C30+C31 -> -141008 | D32: =D30+D31 -> -127579 | E32: =E30+E31 -> -117150 | F32: =F30+F31 -> -102721 | G32: =G30+G31 -> -92292
A34: SUPERÁVIT/(DÉFICIT) DO EXERCÍCIO | B34: =B23+B32 -> -555163 | C34: =C23+C32 -> -611504 | D34: =D23+D32 -> -462918 | E34: =E23+E32 -> -485313 | F34: =F23+F32 -> -338178 | G34: =G23+G32 -> -346856 | H34: EBIT + Resultado financeiro
A36: GERAÇÃO DE CAIXA OPERACIONAL
A37: Superávit ajustado (Superávit + amortização atletas + depreciação) | B37: =B34+B24+B25 -> -448163 | C37: =C34+C24+C25 -> -499504 | D37: =D34+D24+D25 -> -360918 | E37: =E34+E24+E25 -> -378313 | F37: =F34+F24+F25 -> -241178 | G37: =G34+G24+G25 -> -244856 | H37: Reverso de itens não-caixa
A38: Variação esperada em contas a receber (sinal positivo = redução) | B38: =-ROUND(B7*0.1,0) -> -7000 | C38: =-ROUND(C7*0.1,0) -> -6000 | D38: =-ROUND(D7*0.1,0) -> -13000 | E38: =-ROUND(E7*0.1,0) -> -11000 | F38: =-ROUND(F7*0.1,0) -> -21800 | G38: =-ROUND(G7*0.1,0) -> -18000 | H38: Premissa simplificada: -10% do volume de cessões (algumas vendas viram caixa, outras viram receivable)
A39: Variação esperada em contas a pagar (recorrente) | B39: =ROUND(-(B14+B15)*0.05,0) -> 28427 | C39: =ROUND(-(C14+C15)*0.05,0) -> 30133 | D39: =ROUND(-(D14+D15)*0.05,0) -> 27482 | E39: =ROUND(-(E14+E15)*0.05,0) -> 28604 | F39: =ROUND(-(F14+F15)*0.05,0) -> 26976 | G39: =ROUND(-(G14+G15)*0.05,0) -> 27561 | H39: +5% sobre custos recorrentes (Flu sempre amplia passivo operacional)
A40: Caixa operacional antes de Capex em jogadores | B40: =B37+B38+B39 -> -426736 | C40: =C37+C38+C39 -> -475371 | D40: =D37+D38+D39 -> -346436 | E40: =E37+E38+E39 -> -360709 | F40: =F37+F38+F39 -> -236002 | G40: =G37+G38+G39 -> -235295
A42: FLUXO DE INVESTIMENTO EM ATLETAS
A43: Capex comprometido no ano (intangível) | B43: =Premissas_Runway!B34 -> 162000 | C43: =Premissas_Runway!B35 -> 80000 | D43: =Premissas_Runway!C34 -> 180000 | E43: =Premissas_Runway!C35 -> 120000 | F43: =Premissas_Runway!D34 -> 250000 | G43: =Premissas_Runway!D35 -> 200000 | H43: Da Premissas_Runway
A44: (−) % que vira saída de caixa no mesmo ano | B44: =-ROUND(B43*Premissas_Runway!B36,0) -> -81000 | C44: =-ROUND(C43*Premissas_Runway!B36,0) -> -40000 | D44: =-ROUND(D43*Premissas_Runway!C36,0) -> -99000 | E44: =-ROUND(E43*Premissas_Runway!C36,0) -> -66000 | F44: =-ROUND(F43*Premissas_Runway!D36,0) -> -150000 | G44: =-ROUND(G43*Premissas_Runway!D36,0) -> -120000
A45: (−) Amortização de parcelas de capex antigo | B45: =-Premissas_Runway!B37 -> -150000 | C45: =-Premissas_Runway!B38 -> -130000 | D45: =-Premissas_Runway!C37 -> -130000 | E45: =-Premissas_Runway!C38 -> -110000 | F45: =-Premissas_Runway!D37 -> -110000 | G45: =-Premissas_Runway!D38 -> -90000 | H45: Da Premissas_Runway
A46: Caixa recebido de vendas de atletas (estimado 80% da receita de cessão) | B46: =ROUND(B7*0.8,0) -> 56000 | C46: =ROUND(C7*0.8,0) -> 48000 | D46: =ROUND(D7*0.8,0) -> 104000 | E46: =ROUND(E7*0.8,0) -> 88000 | F46: =ROUND(F7*0.8,0) -> 174400 | G46: =ROUND(G7*0.8,0) -> 144000 | H46: 20% fica em conta a receber. Histórico Flu 2025: recebido ~70% do reconhecido
...

Sheet Resumo_Cenarios
A1: FLUMINENSE FOOTBALL CLUB — Resumo dos Cenários 2026-2027
A2: Visão consolidada lado-a-lado dos 3 cenários. Valores derivados do Modelo_Runway.
B3: PESSIMISTA | D3: BASE | F3: OTIMISTA
B4: 2026 | C4: 2027 | D4: 2026 | E4: 2027 | F4: 2026 | G4: 2027 | H4: Análise
A5: RECEITAS
A6: Receita Total Bruta | B6: =Modelo_Runway!B9 -> 549515 | C6: =Modelo_Runway!C9 -> 522873 | D6: =Modelo_Runway!D9 -> 608445 | E6: =Modelo_Runway!E9 -> 608704 | F6: =Modelo_Runway!F9 -> 722426 | G6: =Modelo_Runway!G9 -> 723367
A7: Receita Operacional Líquida | B7: =Modelo_Runway!B11 -> 406641 | C7: =Modelo_Runway!C11 -> 386926 | D7: =Modelo_Runway!D11 -> 450249 | E7: =Modelo_Runway!E11 -> 450441 | F7: =Modelo_Runway!F11 -> 534595 | G7: =Modelo_Runway!G11 -> 535292
A8: Cessão de atletas (parte da receita bruta) | B8: =Modelo_Runway!B7 -> 70000 | C8: =Modelo_Runway!C7 -> 60000 | D8: =Modelo_Runway!D7 -> 130000 | E8: =Modelo_Runway!E7 -> 110000 | F8: =Modelo_Runway!F7 -> 218000 | G8: =Modelo_Runway!G7 -> 180000
A9: Premiação CONMEBOL (parte da receita bruta) | B9: =Modelo_Runway!B8 -> 41600 | C9: =Modelo_Runway!C8 -> 16200 | D9: =Modelo_Runway!D8 -> 27775 | E9: =Modelo_Runway!E8 -> 25500 | F9: =Modelo_Runway!F8 -> 36750 | G9: =Modelo_Runway!G8 -> 33600
A11: RESULTADO
A12: EBITDA | B12: =Modelo_Runway!B26 -> -296726 | C12: =Modelo_Runway!C26 -> -358496 | D12: =Modelo_Runway!D26 -> -233339 | E12: =Modelo_Runway!E26 -> -261163 | F12: =Modelo_Runway!F26 -> -138457 | G12: =Modelo_Runway!G26 -> -152564
A13: Margem EBITDA | B13: =Modelo_Runway!B27 -> -0.72970015 | C13: =Modelo_Runway!C27 -> -0.92652342 | D13: =Modelo_Runway!D27 -> -0.51824435 | E13: =Modelo_Runway!E27 -> -0.57979402 | F13: =Modelo_Runway!F27 -> -0.25899419 | G13: =Modelo_Runway!G27 -> -0.2850108
A14: EBIT | B14: =Modelo_Runway!B23 -> -403726 | C14: =Modelo_Runway!C23 -> -470496 | D14: =Modelo_Runway!D23 -> -335339 | E14: =Modelo_Runway!E23 -> -368163 | F14: =Modelo_Runway!F23 -> -235457 | G14: =Modelo_Runway!G23 -> -254564
A15: Superávit/(Déficit) do Exercício | B15: =Modelo_Runway!B34 -> -555163 | C15: =Modelo_Runway!C34 -> -611504 | D15: =Modelo_Runway!D34 -> -462918 | E15: =Modelo_Runway!E34 -> -485313 | F15: =Modelo_Runway!F34 -> -338178 | G15: =Modelo_Runway!G34 -> -346856
A17: CAIXA
A18: Caixa Operacional (antes capex atletas) | B18: =Modelo_Runway!B40 -> -426736 | C18: =Modelo_Runway!C40 -> -475371 | D18: =Modelo_Runway!D40 -> -346436 | E18: =Modelo_Runway!E40 -> -360709 | F18: =Modelo_Runway!F40 -> -236002 | G18: =Modelo_Runway!G40 -> -235295
A19: Caixa Investimento em Atletas | B19: =Modelo_Runway!B47 -> -175000 | C19: =Modelo_Runway!C47 -> -122000 | D19: =Modelo_Runway!D47 -> -125000 | E19: =Modelo_Runway!E47 -> -88000 | F19: =Modelo_Runway!F47 -> -85600 | G19: =Modelo_Runway!G47 -> -66000
A20: Caixa de Financiamento | B20: =Modelo_Runway!B52 -> 30000 | C20: =Modelo_Runway!C52 -> 25000 | D20: =Modelo_Runway!D52 -> 40000 | E20: =Modelo_Runway!E52 -> 35000 | F20: =Modelo_Runway!F52 -> 50000 | G20: =Modelo_Runway!G52 -> 45000
A21: Erosão FIFA Mundial (impacto único 2026) | B21: =Modelo_Runway!B56 -> -79296 | C21: =Modelo_Runway!C56 -> 0 | D21: =Modelo_Runway!D56 -> -67968 | E21: =Modelo_Runway!E56 -> 0 | F21: =Modelo_Runway!F56 -> -47578 | G21: =Modelo_Runway!G56 -> 0
A22: Variação Total de Caixa | B22: =Modelo_Runway!B57 -> -571736 | C22: =Modelo_Runway!C57 -> -572371 | D22: =Modelo_Runway!D57 -> -431436 | E22: =Modelo_Runway!E57 -> -413709 | F22: =Modelo_Runway!F57 -> -271602 | G22: =Modelo_Runway!G57 -> -256295
A23: Caixa Final | B23: =Modelo_Runway!B58 -> -616506 | C23: =Modelo_Runway!C58 -> -1188877 | D23: =Modelo_Runway!D58 -> -464878 | E23: =Modelo_Runway!E58 -> -878587 | F23: =Modelo_Runway!F58 -> -284654 | G23: =Modelo_Runway!G58 -> -540949
A25: SOLVÊNCIA E SUSTENTABILIDADE
A26: Caixa final em meses de folha | B26: =Modelo_Runway!B61 -> -15.580629 | C26: =Modelo_Runway!C61 -> -28.34512 | D26: =Modelo_Runway!D61 -> -12.200482 | E26: =Modelo_Runway!E61 -> -22.17119 | F26: =Modelo_Runway!F61 -> -7.6170776 | G26: =Modelo_Runway!G61 -> -14.191463
A27: Dívida total projetada | B27: =Modelo_Runway!B62 -> 1072916 | C27: =Modelo_Runway!C62 -> 1097916 | D27: =Modelo_Runway!D62 -> 1082916 | E27: =Modelo_Runway!E62 -> 1117916 | F27: =Modelo_Runway!F62 -> 1092916 | G27: =Modelo_Runway!G62 -> 1137916
A28: Compromissos com transferências em aberto | B28: =Modelo_Runway!B63 -> 256192 | C28: =Modelo_Runway!C63 -> 206192 | D28: =Modelo_Runway!D63 -> 294192 | E28: =Modelo_Runway!E63 -> 304192 | F28: =Modelo_Runway!F63 -> 384192 | G28: =Modelo_Runway!G63 -> 494192

Sheet Caminho_A_Trajetoria
A1: FLUMINENSE FOOTBALL CLUB — Caminho A: A Trajetória de Continuidade
A2: Tese: o Fluminense NÃO está em rota de recuperação judicial como o Botafogo. Está numa trajetória de "continuidade operacional viável" sustentada por (i) cessões pontuais de atletas, (ii) descontos fiscais não recorrentes, (iii) eventos extraordinários como o FIFA Mundial. A operação dia-a-dia permanece estruturalmente deficitária, mas o clube tem ativos e relacionamentos suficientes para manter o ciclo girando — desde que essas alavancas continuem disponíveis.
A4: Indicador | B4: Pessimista | C4: Base | D4: Otimista | E4: Interpretação
A5: TRAJETÓRIA AGREGADA 2026-2027
A6: EBITDA agregado 2026+2027 (R$ mil) | B6: =Modelo_Runway!B26+Modelo_Runway!C26 -> -655222 | C6: =Modelo_Runway!D26+Modelo_Runway!E26 -> -494502 | D6: =Modelo_Runway!F26+Modelo_Runway!G26 -> -291021 | E6: Soma do EBITDA dos dois anos. Negativo em todos os cenários — a operação dia-a-dia continua queimando dinheiro.
A7: Receita de cessão acumulada 2026+2027 | B7: =Modelo_Runway!B7+Modelo_Runway!C7 -> 130000 | C7: =Modelo_Runway!D7+Modelo_Runway!E7 -> 240000 | D7: =Modelo_Runway!F7+Modelo_Runway!G7 -> 398000 | E7: Quanto o clube precisa vender para sustentar o ciclo. Pessimista: R$ 130M | Otimista: R$ 398M
A8: Caixa final 2027 (posição absoluta) | B8: =Modelo_Runway!C58 -> -1188877 | C8: =Modelo_Runway!E58 -> -878587 | D8: =Modelo_Runway!G58 -> -540949 | E8: Negativo em todos cenários. Mesmo no otimista, sem novo ciclo de cessões em 2028, o caixa é insustentável.
A9: Variação acumulada de caixa 2026+2027 | B9: =Modelo_Runway!B57+Modelo_Runway!C57 -> -1144107 | C9: =Modelo_Runway!D57+Modelo_Runway!E57 -> -845145 | D9: =Modelo_Runway!F57+Modelo_Runway!G57 -> -527897 | E9: Queima estrutural de caixa. Esse é o tamanho do problema a ser resolvido por refinanciamento, leilões TRT e novas cessões.
A11: CONDIÇÕES PARA O CAMINHO A SE MANTER VIÁVEL
A12: Necessidade de cessões adicionais 2028+ (estimado) | B12: =ABS(Modelo_Runway!C58)*0.5 -> 594438.5 | C12: =ABS(Modelo_Runway!E58)*0.5 -> 439293.5 | D12: =ABS(Modelo_Runway!G58)*0.5 -> 270474.5 | E12: Estimativa de 50% do déficit acumulado projetado de caixa, supondo que metade é refinanciada e metade vem de venda de ativos
A13: Premiação CONMEBOL agregada 2026+2027 | B13: =Modelo_Runway!B8+Modelo_Runway!C8 -> 57800 | C13: =Modelo_Runway!D8+Modelo_Runway!E8 -> 53275 | D13: =Modelo_Runway!F8+Modelo_Runway!G8 -> 70350 | E13: Receita de premiação que NÃO é controlável pelo Flu — depende de classificação esportiva
A14: Dívida fiscal projetada (final 2027) | B14: =Modelo_Runway!C62 -> 1097916 | C14: =Modelo_Runway!E62 -> 1117916 | D14: =Modelo_Runway!G62 -> 1137916 | E14: Cresce em todos cenários. Risco principal: nova transação tributária pode não ser tão generosa quanto a de 2025.
A16: GATILHOS DE STRESS
A17: Gatilho 1: Não classificação a Libertadores 2027 | B17: Confirmado | C17: Provável | D17: Risco | E17: Pessimista já assume cenário de queda em 2026; Base e Otimista pressupõem reclassificação em 2026
A18: Gatilho 2: Aumento de juros do parcelamento PGFN | B18: Confirmado | C18: Risco moderado | D18: Não esperado | E18: Recente transação PGFN nov/2025 deu R$ 90M de desconto. Selic alta + perda de elegibilidade pode anular esse benefício
A19: Gatilho 3: Erosão de receita do dia-a-dia (sócios, bilheteria) | B19: Em curso | C19: Estável | D19: Recuperação | E19: Sócio Futebol já caiu de R$ 70M (2024) para R$ 60M (2025). Bilheteria depende de campanhas esportivas
A20: Gatilho 4: Não recebimento integral da Premiação FIFA | B20: Provável (35%) | C20: Provável (30%) | D20: Negociado (21%) | E20: Já reconhecida em 2025 mas com fluxo em 2026 sujeito à retenção americana
A23: CONCLUSÃO DA TESE
A24: O Fluminense não está em rota de recuperação judicial como o Botafogo SAF em 2025. Mas também não está em rota de saúde financeira. A operação dia-a-dia (sem cessões de atletas, sem premiações extraordinárias, sem descontos fiscais únicos) queima cerca de R$ 250-440 milhões por ano. O clube se mantém viável porque consegue MANUFATURAR eventos extraordinários a cada ciclo: classificação para Libertadores e Mundiais que trazem premiação, venda de atletas que transforma 3-5 ativos por ano em centenas de milhões de reais, transações tributárias com a Receita Federal que reduzem o estoque de dívida. A pergunta-chave para os próximos 24 meses não é "o Fluminense vai quebrar?", mas sim "o Fluminense vai conseguir reproduzir o ciclo de eventos não recorrentes em 2027 e 2028?". Sem o motor de uma nova venda casada (Wolverhampton/Al Ahli/Brighton em 2024-2025) e sem um novo evento como o Mundial (que volta em 2029), o caixa fica criticamente apertado e a dependência de novas transações fiscais (como a de nov/2025) cresce.

Sheet Caminho_B_SAF
A1: FLUMINENSE FOOTBALL CLUB — Caminho B: SAF (Proposta LZ Esports/Lazuli Partners)
A2: Modelagem da proposta em análise: venda de 65% do futebol para bloco de ~40 investidores, com 35% mantidos pela associação. Aporte total R$ 6,9 bilhões em 10 anos, focado em quitação de dívidas (R$ 870M), folha, atletas, e infraestrutura (CT e Xerém). Status: avaliação por comissões internas e externas; pendente de aprovação do Conselho Deliberativo e Assembleia Geral.
B4: 2026 | C4: 2027 | D4: 2028 | E4: 2029 | F4: 2030 | G4: 2031 | H4: 2032 | I4: 2033 | J4: 2034 | K4: 2035 | L4: Total 10 anos | M4: Justificativa / Fonte
A5: CRONOGRAMA DE APORTE LZ/LAZULI (R$ MIL)
A6: Aporte total anual (entrada de capital novo) | B6: 1500000 | C6: 1200000 | D6: 900000 | E6: 700000 | F6: 600000 | G6: 500000 | H6: 400000 | I6: 400000 | J6: 350000 | K6: 350000 | L6: =SUM(B6:K6) -> 6900000 | M6: Front-loaded para destravar dívidas. Total dos 10 anos = R$ 6,9 bi (premissa do deal LZ/Lazuli). Pessimista: aporte pode ser menor ou diluído
A8: ALOCAÇÃO DO APORTE — % POR DESTINO
A9: % para quitação/refinanciamento de dívida | B9: 0.5 | C9: 0.4 | D9: 0.25 | E9: 0.15 | F9: 0.1 | G9: 0.05 | H9: 0.05 | I9: 0.05 | J9: 0.05 | K9: 0.05 | M9: Anos 1-2 prioritários para destravar passivo. Total R$ 870M de dívida principal a ser equacionada (Fonte: proposta LZ)
A10: % para aquisição de atletas (capex elenco) | B10: 0.2 | C10: 0.25 | D10: 0.3 | E10: 0.35 | F10: 0.35 | G10: 0.4 | H10: 0.4 | I10: 0.4 | J10: 0.4 | K10: 0.4 | M10: Cresce após quitação inicial — objetivo de competitividade sustentada
A11: % para elevação da folha salarial | B11: 0.15 | C11: 0.2 | D11: 0.25 | E11: 0.3 | F11: 0.3 | G11: 0.3 | H11: 0.3 | I11: 0.3 | J11: 0.3 | K11: 0.3 | M11: Atrair e reter elenco — premissa de R$ 200-300M/ano em folha SAF após estabilização
A12: % para infraestrutura (CT Carlos Castilho + Xerém + estádio) | B12: 0.1 | C12: 0.1 | D12: 0.15 | E12: 0.15 | F12: 0.2 | G12: 0.2 | H12: 0.2 | I12: 0.2 | J12: 0.2 | K12: 0.2 | M12: Investimento capex em ativos fixos — agrega valor patrimonial à SAF
A13: % reserva operacional / contingências | B13: 0.05 | C13: 0.05 | D13: 0.05 | E13: 0.05 | F13: 0.05 | G13: 0.05 | H13: 0.05 | I13: 0.05 | J13: 0.05 | K13: 0.05 | M13: Buffer para imprevistos e capital de giro
A14: Soma das alocações (validação = 100%) | B14: =B9+B10+B11+B12+B13 -> 1 | C14: =C9+C10+C11+C12+C13 -> 1 | D14: =D9+D10+D11+D12+D13 -> 1 | E14: =E9+E10+E11+E12+E13 -> 1 | F14: =F9+F10+F11+F12+F13 -> 1 | G14: =G9+G10+G11+G12+G13 -> 1 | H14: =H9+H10+H11+H12+H13 -> 1 | I14: =I9+I10+I11+I12+I13 -> 1 | ... K14: =K9+K10+K11+K12+K13 -> 1
A16: VALORES ABSOLUTOS POR DESTINO (R$ MIL)
A17: Quitação/refinanciamento de dívida | B17: =ROUND(B6*B9,0) -> 750000 | C17: =ROUND(C6*C9,0) -> 480000 | D17: =ROUND(D6*D9,0) -> 225000 | E17: =ROUND(E6*E9,0) -> 105000 | F17: =ROUND(F6*F9,0) -> 60000 | G17: =ROUND(G6*G9,0) -> 25000 | H17: =ROUND(H6*H9,0) -> 20000 | I17: =ROUND(I6*I9,0) -> 20000 | ... K17: =ROUND(K6*K9,0) -> 17500 | L17: =SUM(B17:K17) -> 1720000 | M17: Aporte × % dívida
A18: Aquisição de atletas | B18: =ROUND(B6*B10,0) -> 300000 | C18: =ROUND(C6*C10,0) -> 300000 | D18: =ROUND(D6*D10,0) -> 270000 | E18: =ROUND(E6*E10,0) -> 245000 | F18: =ROUND(F6*F10,0) -> 210000 | G18: =ROUND(G6*G10,0) -> 200000 | H18: =ROUND(H6*H10,0) -> 160000 | I18: =ROUND(I6*I10,0) -> 160000 | ... K18: =ROUND(K6*K10,0) -> 140000 | L18: =SUM(B18:K18) -> 2125000 | M18: Aporte × % atletas
A19: Elevação da folha salarial | B19: =ROUND(B6*B11,0) -> 225000 | C19: =ROUND(C6*C11,0) -> 240000 | D19: =ROUND(D6*D11,0) -> 225000 | E19: =ROUND(E6*E11,0) -> 210000 | F19: =ROUND(F6*F11,0) -> 180000 | G19: =ROUND(G6*G11,0) -> 150000 | H19: =ROUND(H6*H11,0) -> 120000 | I19: =ROUND(I6*I11,0) -> 120000 | ... K19: =ROUND(K6*K11,0) -> 105000 | L19: =SUM(B19:K19) -> 1680000 | M19: Aporte × % folha
